NODELIST=27.122.137.19
MASTER_ADDR=
Use GPU: 3 for training
==> Making model..
The number of parameters of model is 24253410
==> Preparing data..
Files already downloaded and verified
Use GPU: 0 for training
==> Making model..
The number of parameters of model is 24253410
==> Preparing data..
Files already downloaded and verified
Use GPU: 1 for training
==> Making model..
The number of parameters of model is 24253410
==> Preparing data..
Files already downloaded and verified
Use GPU: 2 for training
==> Making model..
The number of parameters of model is 24253410
==> Preparing data..
Files already downloaded and verified
Epoch: [0/196]| loss: 2.323 | acc: 14.062 | batch time: 15.744s 
Epoch: [20/196]| loss: 2.051 | acc: 23.958 | batch time: 0.469s 
Epoch: [40/196]| loss: 1.910 | acc: 28.849 | batch time: 0.477s 
Epoch: [60/196]| loss: 1.814 | acc: 32.659 | batch time: 0.562s 
Epoch: [80/196]| loss: 1.745 | acc: 35.494 | batch time: 0.552s 
Epoch: [100/196]| loss: 1.674 | acc: 38.382 | batch time: 0.519s 
Epoch: [120/196]| loss: 1.609 | acc: 40.974 | batch time: 0.482s 
Epoch: [140/196]| loss: 1.553 | acc: 43.141 | batch time: 0.582s 
Epoch: [160/196]| loss: 1.503 | acc: 44.992 | batch time: 0.613s 
Epoch: [180/196]| loss: 1.465 | acc: 46.487 | batch time: 0.475s 
Training time 0:02:15.839335
Exception in thread Thread-1:
Traceback (most recent call last):
  File "/usr/lib/python3.8/threading.py", line 932, in _bootstrap_inner
    self.run()
  File "/home/slurm-master/.local/lib/python3.8/site-packages/tensorboardX/event_file_writer.py", line 202, in run
    data = self._queue.get(True, queue_wait_duration)
  File "/usr/lib/python3.8/multiprocessing/queues.py", line 111, in get
    res = self._recv_bytes()
  File "/usr/lib/python3.8/multiprocessing/connection.py", line 216, in recv_bytes
    buf = self._recv_bytes(maxlength)
  File "/usr/lib/python3.8/multiprocessing/connection.py", line 414, in _recv_bytes
    buf = self._recv(4)
  File "/usr/lib/python3.8/multiprocessing/connection.py", line 383, in _recv
    raise EOFError
EOFError
Epoch: [0/196]| loss: 2.353 | acc: 6.250 | batch time: 15.684s 
Epoch: [20/196]| loss: 2.018 | acc: 23.512 | batch time: 0.432s 
Epoch: [40/196]| loss: 1.897 | acc: 28.011 | batch time: 0.498s 
Epoch: [60/196]| loss: 1.798 | acc: 32.223 | batch time: 0.546s 
Epoch: [80/196]| loss: 1.717 | acc: 35.455 | batch time: 0.598s 
Epoch: [100/196]| loss: 1.641 | acc: 38.800 | batch time: 0.492s 
Epoch: [120/196]| loss: 1.586 | acc: 41.012 | batch time: 0.507s 
Epoch: [140/196]| loss: 1.532 | acc: 43.285 | batch time: 0.655s 
Epoch: [160/196]| loss: 1.489 | acc: 44.788 | batch time: 0.577s 
Epoch: [180/196]| loss: 1.446 | acc: 46.487 | batch time: 0.547s 
Training time 0:02:15.883058
Exception in thread Thread-1:
Traceback (most recent call last):
  File "/usr/lib/python3.8/threading.py", line 932, in _bootstrap_inner
    self.run()
  File "/home/slurm-master/.local/lib/python3.8/site-packages/tensorboardX/event_file_writer.py", line 202, in run
    data = self._queue.get(True, queue_wait_duration)
  File "/usr/lib/python3.8/multiprocessing/queues.py", line 111, in get
    res = self._recv_bytes()
  File "/usr/lib/python3.8/multiprocessing/connection.py", line 216, in recv_bytes
    buf = self._recv_bytes(maxlength)
  File "/usr/lib/python3.8/multiprocessing/connection.py", line 414, in _recv_bytes
    buf = self._recv(4)
  File "/usr/lib/python3.8/multiprocessing/connection.py", line 383, in _recv
    raise EOFError
EOFError
Epoch: [0/196]| loss: 2.334 | acc: 7.812 | batch time: 17.208s 
Epoch: [20/196]| loss: 2.050 | acc: 21.429 | batch time: 0.508s 
Epoch: [40/196]| loss: 1.869 | acc: 28.697 | batch time: 0.508s 
Epoch: [60/196]| loss: 1.793 | acc: 32.121 | batch time: 0.529s 
Epoch: [80/196]| loss: 1.743 | acc: 34.934 | batch time: 0.584s 
Epoch: [100/196]| loss: 1.673 | acc: 37.887 | batch time: 0.535s 
Epoch: [120/196]| loss: 1.614 | acc: 40.289 | batch time: 0.574s 
Epoch: [140/196]| loss: 1.567 | acc: 42.132 | batch time: 0.633s 
Epoch: [160/196]| loss: 1.517 | acc: 43.983 | batch time: 0.567s 
Epoch: [180/196]| loss: 1.474 | acc: 45.727 | batch time: 0.596s 
Training time 0:02:16.149823
Exception in thread Thread-1:
Traceback (most recent call last):
  File "/usr/lib/python3.8/threading.py", line 932, in _bootstrap_inner
    self.run()
  File "/home/slurm-master/.local/lib/python3.8/site-packages/tensorboardX/event_file_writer.py", line 202, in run
    data = self._queue.get(True, queue_wait_duration)
  File "/usr/lib/python3.8/multiprocessing/queues.py", line 111, in get
    res = self._recv_bytes()
  File "/usr/lib/python3.8/multiprocessing/connection.py", line 216, in recv_bytes
    buf = self._recv_bytes(maxlength)
  File "/usr/lib/python3.8/multiprocessing/connection.py", line 414, in _recv_bytes
    buf = self._recv(4)
  File "/usr/lib/python3.8/multiprocessing/connection.py", line 383, in _recv
    raise EOFError
EOFError
Epoch: [0/196]| loss: 2.301 | acc: 15.625 | batch time: 15.790s 
Epoch: [20/196]| loss: 2.031 | acc: 25.074 | batch time: 0.461s 
Epoch: [40/196]| loss: 1.897 | acc: 29.611 | batch time: 0.491s 
Epoch: [60/196]| loss: 1.817 | acc: 32.582 | batch time: 0.517s 
Epoch: [80/196]| loss: 1.736 | acc: 35.590 | batch time: 0.567s 
Epoch: [100/196]| loss: 1.663 | acc: 38.289 | batch time: 0.581s 
Epoch: [120/196]| loss: 1.606 | acc: 40.651 | batch time: 0.525s 
Epoch: [140/196]| loss: 1.558 | acc: 42.398 | batch time: 0.501s 
Epoch: [160/196]| loss: 1.516 | acc: 43.993 | batch time: 0.620s 
Epoch: [180/196]| loss: 1.478 | acc: 45.485 | batch time: 0.622s 
Training time 0:02:16.005535
Exception in thread Thread-1:
Traceback (most recent call last):
  File "/usr/lib/python3.8/threading.py", line 932, in _bootstrap_inner
    self.run()
  File "/home/slurm-master/.local/lib/python3.8/site-packages/tensorboardX/event_file_writer.py", line 202, in run
    data = self._queue.get(True, queue_wait_duration)
  File "/usr/lib/python3.8/multiprocessing/queues.py", line 111, in get
    res = self._recv_bytes()
  File "/usr/lib/python3.8/multiprocessing/connection.py", line 216, in recv_bytes
    buf = self._recv_bytes(maxlength)
  File "/usr/lib/python3.8/multiprocessing/connection.py", line 414, in _recv_bytes
    buf = self._recv(4)
  File "/usr/lib/python3.8/multiprocessing/connection.py", line 383, in _recv
    raise EOFError
EOFError
