NODELIST=27.122.137.19
MASTER_ADDR=
Use GPU: 0 for training
==> Making model..
The number of parameters of model is 24253410
==> Preparing data..
Files already downloaded and verified
Use GPU: 2 for training
==> Making model..
The number of parameters of model is 24253410
==> Preparing data..
Files already downloaded and verified
Use GPU: 1 for training
==> Making model..
The number of parameters of model is 24253410
==> Preparing data..
Files already downloaded and verified
Use GPU: 3 for training
==> Making model..
The number of parameters of model is 24253410
==> Preparing data..
Files already downloaded and verified
Epoch: [0/196]| loss: 2.334 | acc: 10.938 | batch time: 18.642s 
Epoch: [20/196]| loss: 2.014 | acc: 24.107 | batch time: 0.448s 
Epoch: [40/196]| loss: 1.887 | acc: 28.811 | batch time: 0.523s 
Epoch: [60/196]| loss: 1.804 | acc: 31.993 | batch time: 0.534s 
Epoch: [80/196]| loss: 1.728 | acc: 34.664 | batch time: 0.543s 
Epoch: [100/196]| loss: 1.668 | acc: 37.206 | batch time: 0.507s 
Epoch: [120/196]| loss: 1.621 | acc: 39.062 | batch time: 0.488s 
Epoch: [140/196]| loss: 1.572 | acc: 41.279 | batch time: 0.515s 
Epoch: [160/196]| loss: 1.528 | acc: 43.197 | batch time: 0.499s 
Epoch: [180/196]| loss: 1.483 | acc: 44.976 | batch time: 0.631s 
Training time 0:02:20.976428
Exception in thread Thread-1:
Traceback (most recent call last):
  File "/usr/lib/python3.8/threading.py", line 932, in _bootstrap_inner
Epoch: [0/196]| loss: 2.363 | acc: 7.812 | batch time: 19.516s 
Epoch: [20/196]| loss: 2.021 | acc: 24.033 | batch time: 0.488s 
Epoch: [40/196]| loss: 1.898 | acc: 27.591 | batch time: 0.473s 
Epoch: [60/196]| loss: 1.818 | acc: 31.122 | batch time: 0.517s 
Epoch: [80/196]| loss: 1.765 | acc: 33.372 | batch time: 0.630s 
Epoch: [100/196]| loss: 1.709 | acc: 36.231 | batch time: 0.518s 
Epoch: [120/196]| loss: 1.649 | acc: 38.701 | batch time: 0.538s 
Epoch: [140/196]| loss: 1.595 | acc: 40.913 | batch time: 0.492s 
Epoch: [160/196]| loss: 1.546 | acc: 42.799 | batch time: 0.514s 
Epoch: [180/196]| loss: 1.501 | acc: 44.510 | batch time: 0.539s 
Training time 0:02:20.756794
Exception in thread Thread-1:
Traceback (most recent call last):
  File "/usr/lib/python3.8/threading.py", line 932, in _bootstrap_inner
    self.run()
  File "/home/slurm-master/.local/lib/python3.8/site-packages/tensorboardX/event_file_writer.py", line 202, in run
Epoch: [0/196]| loss: 2.300 | acc: 14.062 | batch time: 18.694s 
Epoch: [20/196]| loss: 2.028 | acc: 22.545 | batch time: 0.529s 
Epoch: [40/196]| loss: 1.879 | acc: 28.620 | batch time: 0.509s 
Epoch: [60/196]| loss: 1.804 | acc: 31.711 | batch time: 0.512s 
Epoch: [80/196]| loss: 1.756 | acc: 33.816 | batch time: 0.616s 
Epoch: [100/196]| loss: 1.709 | acc: 36.046 | batch time: 0.611s 
Epoch: [120/196]| loss: 1.651 | acc: 38.404 | batch time: 0.571s 
Epoch: [140/196]| loss: 1.601 | acc: 40.414 | batch time: 0.529s 
Epoch: [160/196]| loss: 1.549 | acc: 42.314 | batch time: 0.544s 
Epoch: [180/196]| loss: 1.503 | acc: 44.199 | batch time: 0.580s 
Training time 0:02:20.717576
Exception in thread Thread-1:
Traceback (most recent call last):
  File "/usr/lib/python3.8/threading.py", line 932, in _bootstrap_inner
    self.run()
  File "/home/slurm-master/.local/lib/python3.8/site-packages/tensorboardX/event_file_writer.py", line 202, in run
    data = self._queue.get(True, queue_wait_duration)
  File "/usr/lib/python3.8/multiprocessing/queues.py", line 111, in get
    res = self._recv_bytes()
  File "/usr/lib/python3.8/multiprocessing/connection.py", line 216, in recv_bytes
    buf = self._recv_bytes(maxlength)
  File "/usr/lib/python3.8/multiprocessing/connection.py", line 414, in _recv_bytes
    buf = self._recv(4)
  File "/usr/lib/python3.8/multiprocessing/connection.py", line 383, in _recv
    raise EOFError
EOFError
    self.run()
  File "/home/slurm-master/.local/lib/python3.8/site-packages/tensorboardX/event_file_writer.py", line 202, in run
    data = self._queue.get(True, queue_wait_duration)
  File "/usr/lib/python3.8/multiprocessing/queues.py", line 111, in get
    res = self._recv_bytes()
  File "/usr/lib/python3.8/multiprocessing/connection.py", line 216, in recv_bytes
    buf = self._recv_bytes(maxlength)
  File "/usr/lib/python3.8/multiprocessing/connection.py", line 414, in _recv_bytes
    buf = self._recv(4)
  File "/usr/lib/python3.8/multiprocessing/connection.py", line 383, in _recv
    raise EOFError
EOFError
    data = self._queue.get(True, queue_wait_duration)
  File "/usr/lib/python3.8/multiprocessing/queues.py", line 111, in get
    res = self._recv_bytes()
  File "/usr/lib/python3.8/multiprocessing/connection.py", line 216, in recv_bytes
    buf = self._recv_bytes(maxlength)
  File "/usr/lib/python3.8/multiprocessing/connection.py", line 414, in _recv_bytes
    buf = self._recv(4)
  File "/usr/lib/python3.8/multiprocessing/connection.py", line 383, in _recv
    raise EOFError
EOFError
Epoch: [0/196]| loss: 2.361 | acc: 7.812 | batch time: 18.789s 
Epoch: [20/196]| loss: 2.012 | acc: 24.628 | batch time: 0.531s 
Epoch: [40/196]| loss: 1.902 | acc: 28.125 | batch time: 0.499s 
Epoch: [60/196]| loss: 1.825 | acc: 31.071 | batch time: 0.502s 
Epoch: [80/196]| loss: 1.755 | acc: 33.738 | batch time: 0.500s 
Epoch: [100/196]| loss: 1.698 | acc: 36.309 | batch time: 0.610s 
Epoch: [120/196]| loss: 1.642 | acc: 38.611 | batch time: 0.522s 
Epoch: [140/196]| loss: 1.593 | acc: 40.426 | batch time: 0.508s 
Epoch: [160/196]| loss: 1.550 | acc: 42.207 | batch time: 0.480s 
Epoch: [180/196]| loss: 1.513 | acc: 43.810 | batch time: 0.537s 
Training time 0:02:21.099409
Exception in thread Thread-1:
Traceback (most recent call last):
  File "/usr/lib/python3.8/threading.py", line 932, in _bootstrap_inner
    self.run()
  File "/home/slurm-master/.local/lib/python3.8/site-packages/tensorboardX/event_file_writer.py", line 202, in run
    data = self._queue.get(True, queue_wait_duration)
  File "/usr/lib/python3.8/multiprocessing/queues.py", line 111, in get
    res = self._recv_bytes()
  File "/usr/lib/python3.8/multiprocessing/connection.py", line 216, in recv_bytes
    buf = self._recv_bytes(maxlength)
  File "/usr/lib/python3.8/multiprocessing/connection.py", line 414, in _recv_bytes
    buf = self._recv(4)
  File "/usr/lib/python3.8/multiprocessing/connection.py", line 383, in _recv
    raise EOFError
EOFError
/usr/lib/python3.8/multiprocessing/resource_tracker.py:216: UserWarning: resource_tracker: There appear to be 12 leaked semaphore objects to clean up at shutdown
  warnings.warn('resource_tracker: There appear to be %d '
